Workbook

Sheet Instruments
A1: Direct-script instruments for discount-curve interpolation
A3: instrument | B3: definition | C3: handle | D3: market_quote | E3: observation
A4: ptirds-1 | B4: =Instruments!$AA$21 | C4: =Instruments!$AA$22 | D4: =Instruments!$AA$23 | E4: =Instruments!$AA$24
A5: ptirds-2 | B5: =Instruments!$AA$36 | C5: =Instruments!$AA$37 | D5: =Instruments!$AA$38 | E5: =Instruments!$AA$39
A6: ptirds-3 | B6: =Instruments!$AA$51 | C6: =Instruments!$AA$52 | D6: =Instruments!$AA$53 | E6: =Instruments!$AA$54
A7: ptirds-4 | B7: =Instruments!$AA$66 | C7: =Instruments!$AA$67 | D7: =Instruments!$AA$68 | E7: =Instruments!$AA$69
A8: ptirds-5 | B8: =Instruments!$AA$81 | C8: =Instruments!$AA$82 | D8: =Instruments!$AA$83 | E8: =Instruments!$AA$84
A9: ptirds-6 | B9: =Instruments!$AA$96 | C9: =Instruments!$AA$97 | D9: =Instruments!$AA$98 | E9: =Instruments!$AA$99
A10: ptirds-7 | B10: =Instruments!$AA$111 | C10: =Instruments!$AA$112 | D10: =Instruments!$AA$113 | E10: =Instruments!$AA$114
A11: ptirds-8 | B11: =Instruments!$AA$126 | C11: =Instruments!$AA$127 | D11: =Instruments!$AA$128 | E11: =Instruments!$AA$129
A12: ptirds-9 | B12: =Instruments!$AA$141 | C12: =Instruments!$AA$142 | D12: =Instruments!$AA$143 | E12: =Instruments!$AA$144
A13: ptirds-10 | B13: =Instruments!$AA$156 | C13: =Instruments!$AA$157 | D13: =Instruments!$AA$158 | E13: =Instruments!$AA$159
A14: ptirds-11 | B14: =Instruments!$AA$171 | C14: =Instruments!$AA$172 | D14: =Instruments!$AA$173 | E14: =Instruments!$AA$174
A15: ptirds-12 | B15: =Instruments!$AA$188 | C15: =Instruments!$AA$189 | D15: =Instruments!$AA$190 | E15: =Instruments!$AA$191
A16: ptirds-13 | B16: =Instruments!$AA$209 | C16: =Instruments!$AA$210 | D16: =Instruments!$AA$211 | E16: =Instruments!$AA$212
A20: ptirds-1 script definition
A21: kind | B21: key | C21: text | E21: field | F21: value | H21: key | I21: type | J21: unit | K21: role | L21: bindable | M21: lower | N21: upper | O21: lower_inclusive | P21: upper_inclusive | S21: id | T21: kind | U21: receiver | V21: parameter | W21: unit | X21: annuity_sign | Y21: min_abs_annuity | Z21: Definition | AA21: =SCRIPTINSTRUMENTDEFINITION.NEW($A$21:$C$25,$E$21:$F$31,$H$21:$P$23,$S$21:$Y$23,)
A22: Definition | B22: N | C22: 100 | E22: pay_currency | F22: USD | H22: N | I22: Real | J22: Price:USD | K22: Notional | L22: TRUE | M22: 0 | O22: FALSE | P22: TRUE | S22: Price | T22: Price | U22: PAY | W22: Price:USD | Z22: Instrument | AA22: =SCRIPTCALIBRATIONINSTRUMENT.NEW("ptirds-1",AA21,,DATE(2022,1,3))
A23: Definition | B23: K | C23: 0.01 | E23: result_currency | F23: USD | H23: K | I23: Real | J23: Rate | K23: Coupon | L23: TRUE | O23: TRUE | P23: TRUE | S23: ParRate | T23: ParAffineRate | U23: PAY | V23: K | W23: Rate | X23: 1 | Y23: 1e-12 | Z23: Quote | AA23: =CALIBRATIONMARKETQUOTE.NEW("ptirds-1-quote",0.01,"Rate",)
A24: Event | B24: 2022-01-03 | C24: PAY PAYS N*(0.005479452054794521*K) | E24: collateral_currency | F24: USD | Z24: Observation | AA24: =CALIBRATIONOBSERVATION.NEW("ptirds-1-observation",AA22,"ParRate",AA23,1E-10)
A25: Event | B25: 2022-01-03 | C25: PAY PAYS N*(-0.005479452054794521*((1/FIX(IR[USD,DF,2022-01-03,2022-01-01],2022-01-01)-1)/0.005479452054794521)) | E25: collateral_type | F25: OIS
E26: receiver | F26: PAY
E27: notional_parameter | F27: N
E28: settlement | F28: AtEvent
E29: valuation_cashflows | F29: IncludeUnsettledAtValuation
E30: discount_route | F30: USD.OIS
E31: convention_set | F31: dal.fixed-dates/1
A35: ptirds-2 script definition
A36: kind | B36: key | C36: text | E36: field | F36: value | H36: key | I36: type | J36: unit | K36: role | L36: bindable | M36: lower | N36: upper | O36: lower_inclusive | P36: upper_inclusive | S36: id | T36: kind | U36: receiver | V36: parameter | W36: unit | X36: annuity_sign | Y36: min_abs_annuity | Z36: Definition | AA36: =SCRIPTINSTRUMENTDEFINITION.NEW($A$36:$C$40,$E$36:$F$46,$H$36:$P$38,$S$36:$Y$38,)
A37: Definition | B37: N | C37: 100 | E37: pay_currency | F37: USD | H37: N | I37: Real | J37: Price:USD | K37: Notional | L37: TRUE | M37: 0 | O37: FALSE | P37: TRUE | S37: Price | T37: Price | U37: PAY | W37: Price:USD | Z37: Instrument | AA37: =SCRIPTCALIBRATIONINSTRUMENT.NEW("ptirds-2",AA36,,DATE(2022,6,15))
A38: Definition | B38: K | C38: 0.0105 | E38: result_currency | F38: USD | H38: K | I38: Real | J38: Rate | K38: Coupon | L38: TRUE | O38: TRUE | P38: TRUE | S38: ParRate | T38: ParAffineRate | U38: PAY | V38: K | W38: Rate | X38: 1 | Y38: 1e-12 | Z38: Quote | AA38: =CALIBRATIONMARKETQUOTE.NEW("ptirds-2-quote",0.0105,"Rate",)
A39: Event | B39: 2022-06-15 | C39: PAY PAYS N*(0.25205479452054796*K) | E39: collateral_currency | F39: USD | Z39: Observation | AA39: =CALIBRATIONOBSERVATION.NEW("ptirds-2-observation",AA37,"ParRate",AA38,1E-10)
A40: Event | B40: 2022-06-15 | C40: PAY PAYS N*(-0.25205479452054796*((1/FIX(IR[USD,DF,2022-06-15,2022-03-15],2022-03-15)-1)/0.25205479452054796)) | E40: collateral_type | F40: OIS
E41: receiver | F41: PAY
E42: notional_parameter | F42: N
E43: settlement | F43: AtEvent
E44: valuation_cashflows | F44: IncludeUnsettledAtValuation
E45: discount_route | F45: USD.OIS
E46: convention_set | F46: dal.fixed-dates/1
A50: ptirds-3 script definition
...

Sheet LOG_LINEAR
A1: Script yield calibration — LOG_LINEAR
A2: 13 scripted instruments, 14 knots, EXACT solve, AAD Jacobian
A4: Knot dates | B4: =CALIBRATIONDATES.NEW($H$5:$H$18) | D4: field | E4: value | G4: index | H4: knot_date
A5: Geometry | B5: =CURVEINSTRUMENTGEOMETRY.NEW($D$4:$E$14) | D5: today | E5: 44562 | G5: 1 | H5: 44562
A6: Routes | B6: =CURVESCRIPTROUTES.NEW($D$17:$G$18) | D6: currency | E6: USD | G6: 2 | H6: 44635
A7: Market | B7: =CURVEINSTRUMENTMARKET.NEW($D$21:$E$22) | D7: curve_name | E7: ptirds | G7: 3 | H7: 44727
A8: Empty fixings | B8: =MARKETFIXINGSNAPSHOT.NEW(,,) | D8: knot_dates | E8: $B$4 | G8: 4 | H8: 44825
A9: Valuation | B9: =SCRIPTVALUATIONSETTINGS.NEW("ptirds-valuation",$D$25:$E$26,$B$8) | D9: parameterization | E9: LOG_DISCOUNT | G9: 5 | H9: 44916
A10: Solver | B10: =CURVEINSTRUMENTSOLVER.NEW($D$29:$E$35) | D10: knot_policy | E10: INPUT | G10: 6 | H10: 45000
A11: Options | B11: =CURVEINSTRUMENTCALIBRATIONOPTIONS.NEW($D$38:$E$42) | D11: log_df_scheme | E11: LOG_LINEAR | G11: 7 | H11: 45098
A12: Observations | B12: =CALIBRATIONOBSERVATIONS.NEW(Instruments!$E$4:$E$16) | D12: calibrate_discount_curve | E12: TRUE | G12: 8 | H12: 45189
A13: Spec | B13: =CURVEINSTRUMENTCALIBRATIONSPEC.NEW($D$45:$E$50) | D13: target_collateral | E13: OIS | G13: 9 | H13: 45280
A14: Calibration | B14: =CALIBRATE.CURVEINSTRUMENTS($B$13,$B$11) | D14: libor_basis | E14: ACT_365F | G14: 10 | H14: 45366
A15: Status | B15: =CALIBRATIONOUTCOME.GET.STATUS($B$14) | G15: 11 | H15: 45658
A16: Report | B16: =CALIBRATIONOUTCOME.GET.REPORT($B$14) | G16: 12 | H16: 46388
A17: Curve | B17: =CALIBRATIONOUTCOME.GET.CURVE($B$14) | D17: id | E17: projection | F17: collateral | G17: tenor | H17: 47119
D18: USD.OIS | E18: FALSE | F18: OIS | G18: 14 | H18: 48214
D21: field | E21: value
A22: Observation report | D22: routes | E22: $B$6
A23: =CALIBRATIONREPORT.GET.OBSERVATIONS($B$16)
D25: field | E25: value
D26: evaluation_date | E26: 44562
D29: field | E29: value
D30: solve_mode | E30: EXACT
D31: initial_guess | E31: 0.05
D32: smoothing_weight | E32: 1
D33: max_evaluations | E33: 200
D34: max_restarts | E34: 20
D35: fit_norm_tolerance | E35: 1e-08
D38: field | E38: value
D39: evaluation | E39: AutoFast
A40: Fitted parameters | D40: jacobian_mode | E40: AAD
A41: =CALIBRATIONREPORT.GET.PARAMETERS($B$16) | D41: difference_step | E41: 1e-06
D42: compute_quote_jacobian | E42: FALSE
D45: field | E45: value
D46: geometry | E46: $B$5
D47: market | E47: $B$7
D48: valuation | E48: $B$9
D49: observations | E49: $B$12
D50: solver | E50: $B$10

Sheet LOG_CUBIC_NATURAL
A1: Script yield calibration — LOG_CUBIC_NATURAL
A2: 13 scripted instruments, 14 knots, EXACT solve, AAD Jacobian
A4: Knot dates | B4: =CALIBRATIONDATES.NEW($H$5:$H$18) | D4: field | E4: value | G4: index | H4: knot_date
A5: Geometry | B5: =CURVEINSTRUMENTGEOMETRY.NEW($D$4:$E$14) | D5: today | E5: 44562 | G5: 1 | H5: 44562
A6: Routes | B6: =CURVESCRIPTROUTES.NEW($D$17:$G$18) | D6: currency | E6: USD | G6: 2 | H6: 44635
A7: Market | B7: =CURVEINSTRUMENTMARKET.NEW($D$21:$E$22) | D7: curve_name | E7: ptirds | G7: 3 | H7: 44727
A8: Empty fixings | B8: =MARKETFIXINGSNAPSHOT.NEW(,,) | D8: knot_dates | E8: $B$4 | G8: 4 | H8: 44825
A9: Valuation | B9: =SCRIPTVALUATIONSETTINGS.NEW("ptirds-valuation",$D$25:$E$26,$B$8) | D9: parameterization | E9: LOG_DISCOUNT | G9: 5 | H9: 44916
A10: Solver | B10: =CURVEINSTRUMENTSOLVER.NEW($D$29:$E$35) | D10: knot_policy | E10: INPUT | G10: 6 | H10: 45000
A11: Options | B11: =CURVEINSTRUMENTCALIBRATIONOPTIONS.NEW($D$38:$E$42) | D11: log_df_scheme | E11: LOG_CUBIC_NATURAL | G11: 7 | H11: 45098
A12: Observations | B12: =CALIBRATIONOBSERVATIONS.NEW(Instruments!$E$4:$E$16) | D12: calibrate_discount_curve | E12: TRUE | G12: 8 | H12: 45189
A13: Spec | B13: =CURVEINSTRUMENTCALIBRATIONSPEC.NEW($D$45:$E$50) | D13: target_collateral | E13: OIS | G13: 9 | H13: 45280
A14: Calibration | B14: =CALIBRATE.CURVEINSTRUMENTS($B$13,$B$11) | D14: libor_basis | E14: ACT_365F | G14: 10 | H14: 45366
A15: Status | B15: =CALIBRATIONOUTCOME.GET.STATUS($B$14) | G15: 11 | H15: 45658
A16: Report | B16: =CALIBRATIONOUTCOME.GET.REPORT($B$14) | G16: 12 | H16: 46388
A17: Curve | B17: =CALIBRATIONOUTCOME.GET.CURVE($B$14) | D17: id | E17: projection | F17: collateral | G17: tenor | H17: 47119
D18: USD.OIS | E18: FALSE | F18: OIS | G18: 14 | H18: 48214
D21: field | E21: value
A22: Observation report | D22: routes | E22: $B$6
A23: =CALIBRATIONREPORT.GET.OBSERVATIONS($B$16)
D25: field | E25: value
D26: evaluation_date | E26: 44562
D29: field | E29: value
D30: solve_mode | E30: EXACT
D31: initial_guess | E31: 0.05
D32: smoothing_weight | E32: 1
D33: max_evaluations | E33: 200
D34: max_restarts | E34: 20
D35: fit_norm_tolerance | E35: 1e-08
D38: field | E38: value
D39: evaluation | E39: AutoFast
A40: Fitted parameters | D40: jacobian_mode | E40: AAD
A41: =CALIBRATIONREPORT.GET.PARAMETERS($B$16) | D41: difference_step | E41: 1e-06
D42: compute_quote_jacobian | E42: FALSE
D45: field | E45: value
D46: geometry | E46: $B$5
D47: market | E47: $B$7
D48: valuation | E48: $B$9
D49: observations | E49: $B$12
D50: solver | E50: $B$10

Sheet MIXED
A1: Script yield calibration — MIXED
A2: 13 scripted instruments, 14 knots, EXACT solve, AAD Jacobian
A4: Knot dates | B4: =CALIBRATIONDATES.NEW($H$5:$H$18) | D4: field | E4: value | G4: index | H4: knot_date
A5: Geometry | B5: =CURVEINSTRUMENTGEOMETRY.NEW($D$4:$E$14) | D5: today | E5: 44562 | G5: 1 | H5: 44562
A6: Routes | B6: =CURVESCRIPTROUTES.NEW($D$17:$G$18) | D6: currency | E6: USD | G6: 2 | H6: 44635
A7: Market | B7: =CURVEINSTRUMENTMARKET.NEW($D$21:$E$22) | D7: curve_name | E7: ptirds | G7: 3 | H7: 44727
A8: Empty fixings | B8: =MARKETFIXINGSNAPSHOT.NEW(,,) | D8: knot_dates | E8: $B$4 | G8: 4 | H8: 44825
A9: Valuation | B9: =SCRIPTVALUATIONSETTINGS.NEW("ptirds-valuation",$D$25:$E$26,$B$8) | D9: parameterization | E9: LOG_DISCOUNT | G9: 5 | H9: 44916
A10: Solver | B10: =CURVEINSTRUMENTSOLVER.NEW($D$29:$E$35) | D10: knot_policy | E10: INPUT | G10: 6 | H10: 45000
A11: Options | B11: =CURVEINSTRUMENTCALIBRATIONOPTIONS.NEW($D$38:$E$42) | D11: log_df_scheme | E11: MIXED | G11: 7 | H11: 45098
A12: Observations | B12: =CALIBRATIONOBSERVATIONS.NEW(Instruments!$E$4:$E$16) | D12: calibrate_discount_curve | E12: TRUE | G12: 8 | H12: 45189
A13: Spec | B13: =CURVEINSTRUMENTCALIBRATIONSPEC.NEW($D$45:$E$50) | D13: target_collateral | E13: OIS | G13: 9 | H13: 45280
A14: Calibration | B14: =CALIBRATE.CURVEINSTRUMENTS($B$13,$B$11) | D14: libor_basis | E14: ACT_365F | G14: 10 | H14: 45366
A15: Status | B15: =CALIBRATIONOUTCOME.GET.STATUS($B$14) | G15: 11 | H15: 45658
A16: Report | B16: =CALIBRATIONOUTCOME.GET.REPORT($B$14) | G16: 12 | H16: 46388
A17: Curve | B17: =CALIBRATIONOUTCOME.GET.CURVE($B$14) | D17: id | E17: projection | F17: collateral | G17: tenor | H17: 47119
D18: USD.OIS | E18: FALSE | F18: OIS | G18: 14 | H18: 48214
D21: field | E21: value
A22: Observation report | D22: routes | E22: $B$6
A23: =CALIBRATIONREPORT.GET.OBSERVATIONS($B$16)
D25: field | E25: value
D26: evaluation_date | E26: 44562
D29: field | E29: value
D30: solve_mode | E30: EXACT
D31: initial_guess | E31: 0.05
D32: smoothing_weight | E32: 1
D33: max_evaluations | E33: 200
D34: max_restarts | E34: 20
D35: fit_norm_tolerance | E35: 1e-08
D38: field | E38: value
D39: evaluation | E39: AutoFast
A40: Fitted parameters | D40: jacobian_mode | E40: AAD
A41: =CALIBRATIONREPORT.GET.PARAMETERS($B$16) | D41: difference_step | E41: 1e-06
D42: compute_quote_jacobian | E42: FALSE
D45: field | E45: value
D46: geometry | E46: $B$5
D47: market | E47: $B$7
D48: valuation | E48: $B$9
D49: observations | E49: $B$12
D50: solver | E50: $B$10

Sheet Notes
A1: 012.interpolate_curve_script
A3: Initialize DAL | B3: =INIT.GLOBALDATA(1)
A5: The Instruments sheet constructs every definition from dated DAL script source rows. No native swap or native-to-script import function is used.
A6: The three calibration sheets share the same 13 instruments, quotes and 14 knots. Only log_discount_scheme changes: LOG_LINEAR, LOG_CUBIC_NATURAL and MIXED.
A7: ACT/365F accruals are unadjusted; the fixing date is the accrual start. N=100 and each K equals the original instrument's decimal par quote.
A8: The solver uses EXACT, initial guess 0.05, smoothing weight 1, 200 evaluations, 20 restarts and fit_norm_tolerance 1e-8. AAD is selected explicitly.
A9: Run INIT.GLOBALDATA(1), then recalculate the workbook. CALIBRATIONOUTCOME.GET.STATUS should return Succeeded on all three sheets.
A10: Observation and parameter tables are spilled from the typed report. This file contains formulas, not cached results; generating it does not execute Excel.
